<?xml version="1.0" ?>
<!-- =================================================================================== -->
<!-- |    This document was autogenerated by xacro from /home/dukiya/Desktop/Cmd2Action/src/arm_description/urdf/scara.urdf.xacro | -->
<!-- |    EDITING THIS FILE BY HAND IS NOT RECOMMENDED                                 | -->
<!-- =================================================================================== -->
<robot name="scara_robot">
    <link name="world" />
    <joint name="joint_fix" type="fixed">
        <parent link="world" />
        <child link="base_link" />
    </joint>
    <link name="base_link">
        <collision>
            <origin rpy="0 0 0" xyz="0 0 0.2" />
            <geometry>
                <cylinder length="0.4" radius="0.1" />
            </geometry>
        </collision>
        <visual>
            <origin rpy="0 0 0" xyz="0 0 0.2" />
            <geometry>
                <cylinder length="0.4" radius="0.1" />
            </geometry>
            <material name="dark_gray">
                <color rgba="0.4 0.4 0.4 1.0" />
            </material>
        </visual>
        <inertial>
            <origin rpy="0 0 0" xyz="0 0 0.2" />
            <mass value="2.0" />
            <inertia ixx="0.0317" ixy="0.0" ixz="0.0" iyy="0.0317" iyz="0.0" izz="0.01" />
        </inertial>
    </link>
    <gazebo reference="base_link">
        <material>Gazebo/White</material>
        <plugin name="gazebo_ros_control" filename="libgazebo_ros_control.so">
            <robotNamespace>/</robotNamespace>
        </plugin>
    </gazebo>
    <joint name="rotation1" type="revolute">
        <parent link="base_link" />
        <child link="arm1" />
        <origin rpy="0 0 0" xyz="0 0 0.4" />
        <axis xyz="0 0 1" />
        <limit effort="20" lower="-2.6" upper="2.6" velocity="2.0" />
        <dynamics damping="0.1" friction="0.05" />
    </joint>
    <link name="arm1">
        <collision>
            <origin rpy="0 0 0" xyz="0 -0.5 0.05" />
            <geometry>
                <box size="0.1 1.1 0.1" />
            </geometry>
        </collision>
        <visual>
            <origin rpy="0 0 0" xyz="0 -0.5 0.05" />
            <geometry>
                <box size="0.1 1.1 0.1" />
            </geometry>
            <material name="dark_gray">
                <color rgba="0.4 0.4 0.4 1.0" />
            </material>
        </visual>
        <inertial>
            <origin rpy="0 0 0" xyz="0 -0.5 0.05" />
            <mass value="1.5" />
            <inertia ixx="0.1525" ixy="0.0" ixz="0.0" iyy="0.0025" iyz="0.0" izz="0.1525" />
        </inertial>
    </link>
    <gazebo reference="arm1">
        <material>Gazebo/White</material>
    </gazebo>
    <joint name="rotation2" type="revolute">
        <parent link="arm1" />
        <child link="arm2" />
        <origin rpy="0 0 0" xyz="0 -1.0 0.1" />
        <axis xyz="0 0 1" />
        <limit effort="15" lower="-3.00" upper="3.00" velocity="2.0" />
        <dynamics damping="0.1" friction="0.05" />
    </joint>
    <link name="arm2">
        <collision>
            <origin rpy="0 0 0" xyz="0 -0.4 0.05" />
            <geometry>
                <box size="0.1 0.9 0.1" />
            </geometry>
        </collision>
        <visual>
            <origin rpy="0 0 0" xyz="0 -0.4 0.05" />
            <geometry>
                <box size="0.1 0.9 0.1" />
            </geometry>
            <material name="dark_gray">
                <color rgba="0.4 0.4 0.4 1.0" />
            </material>
        </visual>
        <inertial>
            <origin rpy="0 0 0" xyz="0 -0.4 0.05" />
            <mass value="1.0" />
            <inertia ixx="0.0683" ixy="0.0" ixz="0.0" iyy="0.00167" iyz="0.0" izz="0.0683" />
        </inertial>
    </link>
    <gazebo reference="arm2">
        <material>Gazebo/White</material>
    </gazebo>
    <joint name="gripper_joint" type="prismatic">
        <parent link="arm2" />
        <child link="gripper_link" />
        <origin rpy="0 0 0" xyz="0 -0.8 0" />
        <axis xyz="0 0 1" />
        <limit effort="10" lower="-0.8" upper="0.0" velocity="0.1" />
        <dynamics damping="0.1" friction="0.05" />
    </joint>
    <link name="gripper_link">
        <collision>
            <origin rpy="0 0 0" xyz="0 0 -0.1" />
            <geometry>
                <cylinder length="0.2" radius="0.02" />
            </geometry>
        </collision>
        <visual>
            <origin rpy="0 0 0" xyz="0 0 -0.1" />
            <geometry>
                <cylinder length="0.2" radius="0.02" />
            </geometry>
            <material name="dark_gray">
                <color rgba="0.4 0.4 0.4 1.0" />
            </material>
        </visual>
        <inertial>
            <origin rpy="0 0 0" xyz="0 0 -0.1" />
            <mass value="0.5" />
            <inertia ixx="0.00172" ixy="0.0" ixz="0.0" iyy="0.00172" iyz="0.0" izz="0.0001" />
        </inertial>
    </link>
    <gazebo reference="gripper_link">
        <material>Gazebo/White</material>
    </gazebo>
    <joint name="finger1_joint" type="prismatic">
        <parent link="gripper_link" />
        <child link="finger1" />
        <origin rpy="0 0 0" xyz="0 -0.04 -0.23" />
        <axis xyz="0 1 0" />
        <limit effort="20" lower="0.0" upper="0.04" velocity="0.05" />
        <dynamics damping="0.1" friction="0.1" />
    </joint>
    <link name="finger1">
        <collision name="finger1_collision">
            <origin rpy="0 0 0" xyz="0 0 0" />
            <geometry>
                <box size="0.02 0.01 0.02" />
            </geometry>
        </collision>
        <visual>
            <origin rpy="0 0 0" xyz="0 0 0" />
            <geometry>
                <box size="0.02 0.01 0.02" />
            </geometry>
            <material name="dark_gray">
                <color rgba="0.4 0.4 0.4 1.0" />
            </material>
        </visual>
        <inertial>
            <origin rpy="0 0 0" xyz="0 0 0" />
            <mass value="0.1" />
            <inertia ixx="4.17e-6" ixy="0.0" ixz="0.0" iyy="6.67e-6" iyz="0.0" izz="4.17e-6" />
        </inertial>
    </link>
    <gazebo reference="finger1">
        <material>Gazebo/White</material>
        <mu1 value="1000.0" />
        <mu2 value="1000.0" />
        <kp value="1000000.0" />
        <kd value="100.0" />
        <minDepth>0.001</minDepth>
        <maxVel>0.0</maxVel>
    </gazebo>
    <joint name="finger2_joint" type="prismatic">
        <parent link="gripper_link" />
        <child link="finger2" />
        <origin rpy="0 0 0" xyz="0.04 0 -0.23" />
        <axis xyz="1 0 0" />
        <limit effort="20" lower="-0.04" upper="0.0" velocity="0.05" />
        <dynamics damping="0.1" friction="0.1" />
    </joint>
    <link name="finger2">
        <collision name="finger2_collision">
            <origin rpy="0 0 0" xyz="0 0 0" />
            <geometry>
                <box size="0.01 0.02 0.02" />
            </geometry>
        </collision>
        <visual>
            <origin rpy="0 0 0" xyz="0 0 0" />
            <geometry>
                <box size="0.01 0.02 0.02" />
            </geometry>
            <material name="dark_gray">
                <color rgba="0.4 0.4 0.4 1.0" />
            </material>
        </visual>
        <inertial>
            <origin rpy="0 0 0" xyz="0 0 0" />
            <mass value="0.1" />
            <inertia ixx="6.67e-6" ixy="0.0" ixz="0.0" iyy="4.17e-6" iyz="0.0" izz="4.17e-6" />
        </inertial>
    </link>
    <gazebo reference="finger2">
        <material>Gazebo/White</material>
        <mu1 value="1000.0" />
        <mu2 value="1000.0" />
        <kp value="1000000.0" />
        <kd value="100.0" />
        <minDepth>0.001</minDepth>
        <maxVel>0.0</maxVel>
    </gazebo>
    <joint name="finger3_joint" type="prismatic">
        <parent link="gripper_link" />
        <child link="finger3" />
        <origin rpy="0 0 0" xyz="0 0.04 -0.23" />
        <axis xyz="0 1 0" />
        <limit effort="20" lower="-0.04" upper="0.0" velocity="0.05" />
        <dynamics damping="0.1" friction="0.1" />
    </joint>
    <link name="finger3">
        <collision name="finger3_collision">
            <origin rpy="0 0 0" xyz="0 0 0" />
            <geometry>
                <box size="0.02 0.01 0.02" />
            </geometry>
        </collision>
        <visual>
            <origin rpy="0 0 0" xyz="0 0 0" />
            <geometry>
                <box size="0.02 0.01 0.02" />
            </geometry>
            <material name="dark_gray">
                <color rgba="0.4 0.4 0.4 1.0" />
            </material>
        </visual>
        <inertial>
            <origin rpy="0 0 0" xyz="0 0 0" />
            <mass value="0.1" />
            <inertia ixx="4.17e-6" ixy="0.0" ixz="0.0" iyy="6.67e-6" iyz="0.0" izz="4.17e-6" />
        </inertial>
    </link>
    <gazebo reference="finger3">
        <material>Gazebo/White</material>
        <mu1 value="1000.0" />
        <mu2 value="1000.0" />
        <kp value="1000000.0" />
        <kd value="100.0" />
        <minDepth>0.001</minDepth>
        <maxVel>0.0</maxVel>
    </gazebo>
    <joint name="finger4_joint" type="prismatic">
        <parent link="gripper_link" />
        <child link="finger4" />
        <origin rpy="0 0 0" xyz="-0.04 0 -0.23" />
        <axis xyz="1 0 0" />
        <limit effort="20" lower="0.0" upper="0.04" velocity="0.05" />
        <dynamics damping="0.1" friction="0.1" />
    </joint>
    <link name="finger4">
        <collision name="finger4_collision">
            <origin rpy="0 0 0" xyz="0 0 0" />
            <geometry>
                <box size="0.01 0.02 0.02" />
            </geometry>
        </collision>
        <visual>
            <origin rpy="0 0 0" xyz="0 0 0" />
            <geometry>
                <box size="0.01 0.02 0.02" />
            </geometry>
            <material name="dark_gray">
                <color rgba="0.4 0.4 0.4 1.0" />
            </material>
        </visual>
        <inertial>
            <origin rpy="0 0 0" xyz="0 0 0" />
            <mass value="0.1" />
            <inertia ixx="6.67e-6" ixy="0.0" ixz="0.0" iyy="4.17e-6" iyz="0.0" izz="4.17e-6" />
        </inertial>
    </link>
    <gazebo reference="finger4">
        <material>Gazebo/White</material>
        <mu1 value="1000.0" />
        <mu2 value="1000.0" />
        <kp value="1000000.0" />
        <kd value="100.0" />
        <minDepth>0.001</minDepth>
        <maxVel>0.0</maxVel>
    </gazebo>
    <!-- transmissions for ros_control -->
    <transmission name="rotation1_transmission">
        <type>transmission_interface/SimpleTransmission</type>
        <joint name="rotation1">
            <hardwareInterface>hardware_interface/PositionJointInterface</hardwareInterface>
        </joint>
        <actuator name="rotation1_motor">
            <hardwareInterface>hardware_interface/PositionJointInterface</hardwareInterface>
            <mechanicalReduction>1</mechanicalReduction>
        </actuator>
    </transmission>
    <transmission name="rotation2_transmission">
        <type>transmission_interface/SimpleTransmission</type>
        <joint name="rotation2">
            <hardwareInterface>hardware_interface/PositionJointInterface</hardwareInterface>
        </joint>
        <actuator name="rotation2_motor">
            <hardwareInterface>hardware_interface/PositionJointInterface</hardwareInterface>
            <mechanicalReduction>1</mechanicalReduction>
        </actuator>
    </transmission>
    <transmission name="gripper_transmission">
        <type>transmission_interface/SimpleTransmission</type>
        <joint name="gripper_joint">
            <hardwareInterface>hardware_interface/PositionJointInterface</hardwareInterface>
        </joint>
        <actuator name="gripper_motor">
            <hardwareInterface>hardware_interface/PositionJointInterface</hardwareInterface>
            <mechanicalReduction>1</mechanicalReduction>
        </actuator>
    </transmission>
    <transmission name="finger1_transmission">
        <type>transmission_interface/SimpleTransmission</type>
        <joint name="finger1_joint">
            <hardwareInterface>hardware_interface/PositionJointInterface</hardwareInterface>
        </joint>
        <actuator name="finger1_motor">
            <hardwareInterface>hardware_interface/PositionJointInterface</hardwareInterface>
            <mechanicalReduction>1</mechanicalReduction>
        </actuator>
    </transmission>
    <transmission name="finger2_transmission">
        <type>transmission_interface/SimpleTransmission</type>
        <joint name="finger2_joint">
            <hardwareInterface>hardware_interface/PositionJointInterface</hardwareInterface>
        </joint>
        <actuator name="finger2_motor">
            <hardwareInterface>hardware_interface/PositionJointInterface</hardwareInterface>
            <mechanicalReduction>1</mechanicalReduction>
        </actuator>
    </transmission>
    <transmission name="finger3_transmission">
        <type>transmission_interface/SimpleTransmission</type>
        <joint name="finger3_joint">
            <hardwareInterface>hardware_interface/PositionJointInterface</hardwareInterface>
        </joint>
        <actuator name="finger3_motor">
            <hardwareInterface>hardware_interface/PositionJointInterface</hardwareInterface>
            <mechanicalReduction>1</mechanicalReduction>
        </actuator>
    </transmission>
    <transmission name="finger4_transmission">
        <type>transmission_interface/SimpleTransmission</type>
        <joint name="finger4_joint">
            <hardwareInterface>hardware_interface/PositionJointInterface</hardwareInterface>
        </joint>
        <actuator name="finger4_motor">
            <hardwareInterface>hardware_interface/PositionJointInterface</hardwareInterface>
            <mechanicalReduction>1</mechanicalReduction>
        </actuator>
    </transmission>
    <gazebo>
        <plugin filename="libgazebo_ros_control.so" name="gazebo_ros_control" />
    </gazebo>
    <!-- Grasp Fix Plugin for automatic gripper attachment -->
    <gazebo>
        <plugin filename="libgazebo_grasp_fix.so" name="gazebo_grasp_fix">
            <arm>
                <arm_name>scara_arm</arm_name>
                <palm_link>gripper_link</palm_link>
                <!-- 注意: finger链路实际名称为 finger1/finger2/finger3/finger4 -->
                <gripper_link>finger1</gripper_link>
                <gripper_link>finger2</gripper_link>
                <gripper_link>finger3</gripper_link>
                <gripper_link>finger4</gripper_link>
            </arm>
            <forces_angle_tolerance>100</forces_angle_tolerance>
            <update_rate>90</update_rate>
            <grip_count_threshold>8</grip_count_threshold>
            <max_grip_count>12</max_grip_count>
            <release_tolerance>0.001</release_tolerance>
            <disable_collisions_on_attach>true</disable_collisions_on_attach>
            <contact_topic>__default_topic__</contact_topic>
        </plugin>
    </gazebo>
</robot>

